<?xml version="1.0" encoding="utf-8"?>
<!-- =================================================================================== -->
<!-- |    This document was autogenerated by xacro from ugv2.xacro                     | -->
<!-- |    EDITING THIS FILE BY HAND IS NOT RECOMMENDED                                 | -->
<!-- =================================================================================== -->
<robot name="ugv2">
  <material name="silver">
    <color rgba="0.700 0.700 0.700 1.000"/>
  </material>
  <transmission name="rb_joint_tran">
    <type>transmission_interface/SimpleTransmission</type>
    <joint name="rb_joint">
      <hardwareInterface>hardware_interface/EffortJointInterface</hardwareInterface>
    </joint>
    <actuator name="rb_joint_actr">
      <hardwareInterface>hardware_interface/EffortJointInterface</hardwareInterface>
      <mechanicalReduction>1</mechanicalReduction>
    </actuator>
  </transmission>
  <transmission name="rf_joint_tran">
    <type>transmission_interface/SimpleTransmission</type>
    <joint name="rf_joint">
      <hardwareInterface>hardware_interface/EffortJointInterface</hardwareInterface>
    </joint>
    <actuator name="rf_joint_actr">
      <hardwareInterface>hardware_interface/EffortJointInterface</hardwareInterface>
      <mechanicalReduction>1</mechanicalReduction>
    </actuator>
  </transmission>
  <transmission name="lb_joint_tran">
    <type>transmission_interface/SimpleTransmission</type>
    <joint name="lb_joint">
      <hardwareInterface>hardware_interface/EffortJointInterface</hardwareInterface>
    </joint>
    <actuator name="lb_joint_actr">
      <hardwareInterface>hardware_interface/EffortJointInterface</hardwareInterface>
      <mechanicalReduction>1</mechanicalReduction>
    </actuator>
  </transmission>
  <transmission name="lf_joint_tran">
    <type>transmission_interface/SimpleTransmission</type>
    <joint name="lf_joint">
      <hardwareInterface>hardware_interface/EffortJointInterface</hardwareInterface>
    </joint>
    <actuator name="lf_joint_actr">
      <hardwareInterface>hardware_interface/EffortJointInterface</hardwareInterface>
      <mechanicalReduction>1</mechanicalReduction>
    </actuator>
  </transmission>
  <gazebo reference="base_link">
    <material>Gazebo/FlatBlack</material>
  </gazebo>
  <gazebo reference="lidar_1">
    <material>Gazebo/Grey</material>
  </gazebo>
  <gazebo reference="rb_wheel_1">
    <material>Gazebo/Gold</material>
  </gazebo>
  <gazebo reference="rf_wheel_1">
    <material>Gazebo/Gold</material>
  </gazebo>
  <gazebo reference="lb_wheel_1">
    <material>Gazebo/Gold</material>
  </gazebo>
  <gazebo reference="lf_wheel_1">
    <material>Gazebo/Gold</material>
  </gazebo>
  <gazebo reference="pi_camera_1">
    <material>Gazebo/Grey</material>
  </gazebo>
  <gazebo reference="imu_sensor_1">
    <material>Gazebo/Grey</material>
  </gazebo>
  <gazebo reference="base_link">
    <mu1>1.0</mu1>
    <mu2>1.0</mu2>
    <selfCollide>true</selfCollide>
    <gravity>true</gravity>
  </gazebo>
  <gazebo reference="lidar_1">
    <mu1>1.0</mu1>
    <mu2>1.0</mu2>
    <selfCollide>true</selfCollide>
  </gazebo>
  <gazebo reference="rb_wheel_1">
    <mu1>100.0</mu1>
    <mu2>100.0</mu2>
    <selfCollide>true</selfCollide>
  </gazebo>
  <gazebo reference="rf_wheel_1">
    <mu1>100.0</mu1>
    <mu2>100.0</mu2>
    <selfCollide>true</selfCollide>
  </gazebo>
  <gazebo reference="lb_wheel_1">
    <mu1>100.0</mu1>
    <mu2>100.0</mu2>
    <selfCollide>true</selfCollide>
  </gazebo>
  <gazebo reference="lf_wheel_1">
    <mu1>100.0</mu1>
    <mu2>100.0</mu2>
    <selfCollide>true</selfCollide>
  </gazebo>
  <gazebo reference="pi_camera_1">
    <mu1>1.0</mu1>
    <mu2>1.0</mu2>
    <selfCollide>true</selfCollide>
  </gazebo>
  <gazebo reference="imu_sensor_1">
    <mu1>1.0</mu1>
    <mu2>1.0</mu2>
    <selfCollide>true</selfCollide>
  </gazebo>
  <gazebo>
    <plugin filename="libgazebo_ros_control.so" name="control"/>
  </gazebo>
  <!-- ################## Differential Drive Plugin #############################-->
  <gazebo>
    <plugin filename="libgazebo_ros_diff_drive.so" name="differential_drive_controller">
      <!-- Plugin update rate in Hz -->
      <updateRate>10</updateRate>
      <!-- Name of left joint, defaults to `left_joint` -->
      <leftJoint>lf_joint</leftJoint>
      <leftJoint>lb_joint</leftJoint>
      <!-- Name of right joint, defaults to `right_joint` -->
      <rightJoint>rf_joint</rightJoint>
      <leftJoint>rb_joint</leftJoint>
      <!-- The distance from the center of one wheel to the other, in meters, defaults to 0.34 m -->
      <wheelSeparation>0.5380</wheelSeparation>
      <!-- Diameter of the wheels, in meters, defaults to 0.15 m -->
      <wheelDiameter>0.2410</wheelDiameter>
      <!-- Wheel acceleration, in rad/s^2, defaults to 0.0 rad/s^2 -->
      <wheelAcceleration>1.0</wheelAcceleration>
      <!-- Maximum torque which the wheels can produce, in Nm, defaults to 5 Nm -->
      <wheelTorque>20</wheelTorque>
      <!-- Topic to receive geometry_msgs/Twist message commands, defaults to `cmd_vel` -->
      <commandTopic>cmd_vel</commandTopic>
      <!-- Topic to publish nav_msgs/Odometry messages, defaults to `odom` -->
      <odometryTopic>odom</odometryTopic>
      <!-- Odometry frame, defaults to `odom` -->
      <odometryFrame>odom</odometryFrame>
      <!-- Robot frame to calculate odometry from, defaults to `base_footprint` -->
      <robotBaseFrame>base_footprint</robotBaseFrame>
      <!-- Odometry source, 0 for ENCODER, 1 for WORLD, defaults to WORLD -->
      <odometrySource>1</odometrySource>
      <!-- Set to true to publish transforms for the wheel links, defaults to false -->
      <publishWheelTF>true</publishWheelTF>
      <!-- Set to true to publish transforms for the odometry, defaults to true -->
      <publishOdom>true</publishOdom>
      <!-- Set to true to publish sensor_msgs/JointState on /joint_states for the wheel joints, defaults to false -->
      <publishWheelJointState>true</publishWheelJointState>
      <!-- Set to true to swap right and left wheels, defaults to true -->
      <legacyMode>false</legacyMode>
    </plugin>
  </gazebo>
  <!-- ################################ Lidar Plugin ################################################-->
  <!-- hokuyo -->
  <gazebo reference="lidar_1">
    <sensor name="head_hokuyo_sensor" type="gpu_ray">
      <pose>0 0 0 0 0 0</pose>
      <visualize>true</visualize>
      <update_rate>40</update_rate>
      <ray>
        <scan>
          <horizontal>
            <samples>720</samples>
            <resolution>1</resolution>
            <min_angle>-3.14159</min_angle>
            <max_angle>3.14159</max_angle>
          </horizontal>
        </scan>
        <range>
          <min>0.10</min>
          <max>30.0</max>
          <resolution>0.01</resolution>
        </range>
        <noise>
          <type>gaussian</type>
          <!-- Noise parameters based on published spec for Hokuyo laser
               achieving "+-30mm" accuracy at range < 10m.  A mean of 0.0m and
               stddev of 0.01m will put 99.7% of samples within 0.03m of the true
               reading. -->
          <mean>0.0</mean>
          <stddev>0.01</stddev>
        </noise>
      </ray>
      <plugin filename="libgazebo_ros_gpu_laser.so" name="gazebo_ros_head_hokuyo_controller">
        <topicName>/scan</topicName>
        <frameName>lidar_1</frameName>
      </plugin>
    </sensor>
  </gazebo>
  <link name="base_link">
    <inertial>
      <origin rpy="0 0 0" xyz="0.0033907472402908267 -1.2294185660792603e-16 0.04205737762945809"/>
      <mass value="9.291590162574073"/>
      <inertia ixx="0.011185" ixy="0.0" ixz="-0.000965" iyy="0.032552" iyz="0.0" izz="0.037924"/>
    </inertial>
    <visual>
      <origin rpy="0 0 0" xyz="0 0 0"/>
      <geometry>
        <mesh filename="package://ugv2_description/meshes/base_link.stl" scale="0.001 0.001 0.001"/>
      </geometry>
      <material name="silver"/>
    </visual>
    <collision>
      <origin rpy="0 0 0" xyz="0 0 0"/>
      <geometry>
        <mesh filename="package://ugv2_description/meshes/base_link.stl" scale="0.001 0.001 0.001"/>
      </geometry>
    </collision>
  </link>
  <link name="lidar_1">
    <inertial>
      <origin rpy="0 0 0" xyz="-0.007652767991941433 0.00010612194415757128 0.027402719643241688"/>
      <mass value="1.8747231102330029"/>
      <inertia ixx="0.001113" ixy="1e-06" ixz="0.000122" iyy="0.00152" iyz="4e-06" izz="0.001534"/>
    </inertial>
    <visual>
      <origin rpy="0 0 0" xyz="-0.0275 -0.0 -0.08275"/>
      <geometry>
        <mesh filename="package://ugv2_description/meshes/lidar_1.stl" scale="0.001 0.001 0.001"/>
      </geometry>
      <material name="silver"/>
    </visual>
    <collision>
      <origin rpy="0 0 0" xyz="-0.0275 -0.0 -0.08275"/>
      <geometry>
        <mesh filename="package://ugv2_description/meshes/lidar_1.stl" scale="0.001 0.001 0.001"/>
      </geometry>
    </collision>
  </link>
  <link name="rb_wheel_1">
    <inertial>
      <origin rpy="0 0 0" xyz="-1.5849974110970777e-11 0.010079338741740565 4.163336342344337e-17"/>
      <mass value="0.6387176905227006"/>
      <inertia ixx="0.00026" ixy="-0.0" ixz="-0.0" iyy="0.000478" iyz="0.0" izz="0.00026"/>
    </inertial>
    <visual>
      <origin rpy="0 0 0" xyz="0.075 0.08 -0.03775"/>
      <geometry>
        <mesh filename="package://ugv2_description/meshes/rb_wheel_1.stl" scale="0.001 0.001 0.001"/>
      </geometry>
      <material name="silver"/>
    </visual>
    <collision>
      <origin rpy="0 0 0" xyz="0.075 0.08 -0.03775"/>
      <geometry>
        <mesh filename="package://ugv2_description/meshes/rb_wheel_1.stl" scale="0.001 0.001 0.001"/>
      </geometry>
    </collision>
  </link>
  <link name="rf_wheel_1">
    <inertial>
      <origin rpy="0 0 0" xyz="1.568842278310001e-11 0.010079338741740482 1.457167719820518e-16"/>
      <mass value="0.6387176905227065"/>
      <inertia ixx="0.00026" ixy="0.0" ixz="0.0" iyy="0.000478" iyz="0.0" izz="0.00026"/>
    </inertial>
    <visual>
      <origin rpy="0 0 0" xyz="-0.075 0.08 -0.03775"/>
      <geometry>
        <mesh filename="package://ugv2_description/meshes/rf_wheel_1.stl" scale="0.001 0.001 0.001"/>
      </geometry>
      <material name="silver"/>
    </visual>
    <collision>
      <origin rpy="0 0 0" xyz="-0.075 0.08 -0.03775"/>
      <geometry>
        <mesh filename="package://ugv2_description/meshes/rf_wheel_1.stl" scale="0.001 0.001 0.001"/>
      </geometry>
    </collision>
  </link>
  <link name="lb_wheel_1">
    <inertial>
      <origin rpy="0 0 0" xyz="1.0906087977158307e-09 -0.010079338740724489 -1.249000902703301e-16"/>
      <mass value="0.6387176904141518"/>
      <inertia ixx="0.00026" ixy="0.0" ixz="-0.0" iyy="0.000478" iyz="-0.0" izz="0.00026"/>
    </inertial>
    <visual>
      <origin rpy="0 0 0" xyz="0.075 -0.08 -0.03775"/>
      <geometry>
        <mesh filename="package://ugv2_description/meshes/lb_wheel_1.stl" scale="0.001 0.001 0.001"/>
      </geometry>
      <material name="silver"/>
    </visual>
    <collision>
      <origin rpy="0 0 0" xyz="0.075 -0.08 -0.03775"/>
      <geometry>
        <mesh filename="package://ugv2_description/meshes/lb_wheel_1.stl" scale="0.001 0.001 0.001"/>
      </geometry>
    </collision>
  </link>
  <link name="lf_wheel_1">
    <inertial>
      <origin rpy="0 0 0" xyz="-1.090447468432565e-09 -0.010079338740724475 -5.204170427930421e-16"/>
      <mass value="0.6387176904144656"/>
      <inertia ixx="0.00026" ixy="-0.0" ixz="0.0" iyy="0.000478" iyz="0.0" izz="0.00026"/>
    </inertial>
    <visual>
      <origin rpy="0 0 0" xyz="-0.075 -0.08 -0.03775"/>
      <geometry>
        <mesh filename="package://ugv2_description/meshes/lf_wheel_1.stl" scale="0.001 0.001 0.001"/>
      </geometry>
      <material name="silver"/>
    </visual>
    <collision>
      <origin rpy="0 0 0" xyz="-0.075 -0.08 -0.03775"/>
      <geometry>
        <mesh filename="package://ugv2_description/meshes/lf_wheel_1.stl" scale="0.001 0.001 0.001"/>
      </geometry>
    </collision>
  </link>
  <link name="pi_camera_1">
    <inertial>
      <origin rpy="0 0 0" xyz="0.0013912758702941674 -0.00038922935427077444 0.005065651333291829"/>
      <mass value="0.006742869651497955"/>
      <inertia ixx="0.0" ixy="0.0" ixz="-0.0" iyy="0.0" iyz="-0.0" izz="0.0"/>
    </inertial>
    <visual>
      <origin rpy="0 0 0" xyz="-0.1 -0.0 -0.03775"/>
      <geometry>
        <mesh filename="package://ugv2_description/meshes/pi_camera_1.stl" scale="0.001 0.001 0.001"/>
      </geometry>
      <material name="silver"/>
    </visual>
    <collision>
      <origin rpy="0 0 0" xyz="-0.1 -0.0 -0.03775"/>
      <geometry>
        <mesh filename="package://ugv2_description/meshes/pi_camera_1.stl" scale="0.001 0.001 0.001"/>
      </geometry>
    </collision>
  </link>
  <link name="imu_sensor_1">
    <inertial>
      <origin rpy="0 0 0" xyz="8.182177681428845e-05 -6.318495909852773e-06 0.00015585415981772544"/>
      <mass value="0.0005786974233911097"/>
      <inertia ixx="0.0" ixy="0.0" ixz="0.0" iyy="0.0" iyz="0.0" izz="0.0"/>
    </inertial>
    <visual>
      <origin rpy="0 0 0" xyz="-0.0 -0.0 -0.01275"/>
      <geometry>
        <mesh filename="package://ugv2_description/meshes/imu_sensor_1.stl" scale="0.001 0.001 0.001"/>
      </geometry>
      <material name="silver"/>
    </visual>
    <collision>
      <origin rpy="0 0 0" xyz="-0.0 -0.0 -0.01275"/>
      <geometry>
        <mesh filename="package://ugv2_description/meshes/imu_sensor_1.stl" scale="0.001 0.001 0.001"/>
      </geometry>
    </collision>
  </link>
  <joint name="lidar_joint" type="fixed">
    <origin rpy="0 0 0" xyz="0.0275 0.0 0.08275"/>
    <parent link="base_link"/>
    <child link="lidar_1"/>
  </joint>
  <joint name="rb_joint" type="continuous">
    <origin rpy="0 0 0" xyz="-0.075 -0.08 0.03775"/>
    <parent link="base_link"/>
    <child link="rb_wheel_1"/>
    <axis xyz="0.0 1.0 0.0"/>
  </joint>
  <joint name="rf_joint" type="continuous">
    <origin rpy="0 0 0" xyz="0.075 -0.08 0.03775"/>
    <parent link="base_link"/>
    <child link="rf_wheel_1"/>
    <axis xyz="0.0 1.0 0.0"/>
  </joint>
  <joint name="lb_joint" type="continuous">
    <origin rpy="0 0 0" xyz="-0.075 0.08 0.03775"/>
    <parent link="base_link"/>
    <child link="lb_wheel_1"/>
    <axis xyz="0.0 1.0 0.0"/>
  </joint>
  <joint name="lf_joint" type="continuous">
    <origin rpy="0 0 0" xyz="0.075 0.08 0.03775"/>
    <parent link="base_link"/>
    <child link="lf_wheel_1"/>
    <axis xyz="0.0 1.0 0.0"/>
  </joint>
  <joint name="pi_joint" type="fixed">
    <origin rpy="0 0 0" xyz="0.1 0.0 0.03775"/>
    <parent link="base_link"/>
    <child link="pi_camera_1"/>
  </joint>
  <joint name="imu_joint" type="fixed">
    <origin rpy="0 0 0" xyz="0.0 0.0 0.01275"/>
    <parent link="base_link"/>
    <child link="imu_sensor_1"/>
  </joint>
</robot>

