<?xml version="1.0" ?>
<robot name="ugv2" xmlns:xacro="http://www.ros.org/wiki/xacro">

<xacro:include filename="$(find ugv2_description)/urdf/materials.xacro" />
<xacro:include filename="$(find ugv2_description)/urdf/ugv2.trans" />

<xacro:include filename="$(find ugv2_description)/gazebo/ugv2_materials.gazebo" />
<xacro:include filename="$(find ugv2_description)/gazebo/ugv2_physics.gazebo" />
<xacro:include filename="$(find ugv2_description)/gazebo/ugv2_plugins.gazebo" />

<link name="base_link">
  <inertial>
    <origin rpy="0 0 0" xyz="0.0033907472402908267 -1.2294185660792603e-16 0.04205737762945809"/>
    <mass value="9.291590162574073"/>
    <inertia ixx="0.011185" ixy="0.0" ixz="-0.000965" iyy="0.032552" iyz="0.0" izz="0.037924"/>
  </inertial>
  <visual>
    <origin rpy="0 0 0" xyz="0 0 0"/>
    <geometry>
      <mesh filename="package://ugv2_description/meshes/base_link.stl" scale="0.001 0.001 0.001"/>
    </geometry>
    <material name="silver"/>
  </visual>
  <collision>
    <origin rpy="0 0 0" xyz="0 0 0"/>
    <geometry>
      <mesh filename="package://ugv2_description/meshes/base_link.stl" scale="0.001 0.001 0.001"/>
    </geometry>
  </collision>
</link>

<link name="lidar_1">
  <inertial>
    <origin rpy="0 0 0" xyz="-0.007652767991941433 0.00010612194415757128 0.027402719643241688"/>
    <mass value="1.8747231102330029"/>
    <inertia ixx="0.001113" ixy="1e-06" ixz="0.000122" iyy="0.00152" iyz="4e-06" izz="0.001534"/>
  </inertial>
  <visual>
    <origin rpy="0 0 0" xyz="-0.0275 -0.0 -0.08275"/>
    <geometry>
      <mesh filename="package://ugv2_description/meshes/lidar_1.stl" scale="0.001 0.001 0.001"/>
    </geometry>
    <material name="silver"/>
  </visual>
  <collision>
    <origin rpy="0 0 0" xyz="-0.0275 -0.0 -0.08275"/>
    <geometry>
      <mesh filename="package://ugv2_description/meshes/lidar_1.stl" scale="0.001 0.001 0.001"/>
    </geometry>
  </collision>
</link>

<link name="rb_wheel_1">
  <inertial>
    <origin rpy="0 0 0" xyz="-1.5849974110970777e-11 0.010079338741740565 4.163336342344337e-17"/>
    <mass value="0.6387176905227006"/>
    <inertia ixx="0.00026" ixy="-0.0" ixz="-0.0" iyy="0.000478" iyz="0.0" izz="0.00026"/>
  </inertial>
  <visual>
    <origin rpy="0 0 0" xyz="0.075 0.08 -0.03775"/>
    <geometry>
      <mesh filename="package://ugv2_description/meshes/rb_wheel_1.stl" scale="0.001 0.001 0.001"/>
    </geometry>
    <material name="silver"/>
  </visual>
  <collision>
    <origin rpy="0 0 0" xyz="0.075 0.08 -0.03775"/>
    <geometry>
      <mesh filename="package://ugv2_description/meshes/rb_wheel_1.stl" scale="0.001 0.001 0.001"/>
    </geometry>
  </collision>
</link>

<link name="rf_wheel_1">
  <inertial>
    <origin rpy="0 0 0" xyz="1.568842278310001e-11 0.010079338741740482 1.457167719820518e-16"/>
    <mass value="0.6387176905227065"/>
    <inertia ixx="0.00026" ixy="0.0" ixz="0.0" iyy="0.000478" iyz="0.0" izz="0.00026"/>
  </inertial>
  <visual>
    <origin rpy="0 0 0" xyz="-0.075 0.08 -0.03775"/>
    <geometry>
      <mesh filename="package://ugv2_description/meshes/rf_wheel_1.stl" scale="0.001 0.001 0.001"/>
    </geometry>
    <material name="silver"/>
  </visual>
  <collision>
    <origin rpy="0 0 0" xyz="-0.075 0.08 -0.03775"/>
    <geometry>
      <mesh filename="package://ugv2_description/meshes/rf_wheel_1.stl" scale="0.001 0.001 0.001"/>
    </geometry>
  </collision>
</link>

<link name="lb_wheel_1">
  <inertial>
    <origin rpy="0 0 0" xyz="1.0906087977158307e-09 -0.010079338740724489 -1.249000902703301e-16"/>
    <mass value="0.6387176904141518"/>
    <inertia ixx="0.00026" ixy="0.0" ixz="-0.0" iyy="0.000478" iyz="-0.0" izz="0.00026"/>
  </inertial>
  <visual>
    <origin rpy="0 0 0" xyz="0.075 -0.08 -0.03775"/>
    <geometry>
      <mesh filename="package://ugv2_description/meshes/lb_wheel_1.stl" scale="0.001 0.001 0.001"/>
    </geometry>
    <material name="silver"/>
  </visual>
  <collision>
    <origin rpy="0 0 0" xyz="0.075 -0.08 -0.03775"/>
    <geometry>
      <mesh filename="package://ugv2_description/meshes/lb_wheel_1.stl" scale="0.001 0.001 0.001"/>
    </geometry>
  </collision>
</link>

<link name="lf_wheel_1">
  <inertial>
    <origin rpy="0 0 0" xyz="-1.090447468432565e-09 -0.010079338740724475 -5.204170427930421e-16"/>
    <mass value="0.6387176904144656"/>
    <inertia ixx="0.00026" ixy="-0.0" ixz="0.0" iyy="0.000478" iyz="0.0" izz="0.00026"/>
  </inertial>
  <visual>
    <origin rpy="0 0 0" xyz="-0.075 -0.08 -0.03775"/>
    <geometry>
      <mesh filename="package://ugv2_description/meshes/lf_wheel_1.stl" scale="0.001 0.001 0.001"/>
    </geometry>
    <material name="silver"/>
  </visual>
  <collision>
    <origin rpy="0 0 0" xyz="-0.075 -0.08 -0.03775"/>
    <geometry>
      <mesh filename="package://ugv2_description/meshes/lf_wheel_1.stl" scale="0.001 0.001 0.001"/>
    </geometry>
  </collision>
</link>

<link name="pi_camera_1">
  <inertial>
    <origin rpy="0 0 0" xyz="0.0013912758702941674 -0.00038922935427077444 0.005065651333291829"/>
    <mass value="0.006742869651497955"/>
    <inertia ixx="0.0" ixy="0.0" ixz="-0.0" iyy="0.0" iyz="-0.0" izz="0.0"/>
  </inertial>
  <visual>
    <origin rpy="0 0 0" xyz="-0.1 -0.0 -0.03775"/>
    <geometry>
      <mesh filename="package://ugv2_description/meshes/pi_camera_1.stl" scale="0.001 0.001 0.001"/>
    </geometry>
    <material name="silver"/>
  </visual>
  <collision>
    <origin rpy="0 0 0" xyz="-0.1 -0.0 -0.03775"/>
    <geometry>
      <mesh filename="package://ugv2_description/meshes/pi_camera_1.stl" scale="0.001 0.001 0.001"/>
    </geometry>
  </collision>
</link>

<link name="imu_sensor_1">
  <inertial>
    <origin rpy="0 0 0" xyz="8.182177681428845e-05 -6.318495909852773e-06 0.00015585415981772544"/>
    <mass value="0.0005786974233911097"/>
    <inertia ixx="0.0" ixy="0.0" ixz="0.0" iyy="0.0" iyz="0.0" izz="0.0"/>
  </inertial>
  <visual>
    <origin rpy="0 0 0" xyz="-0.0 -0.0 -0.01275"/>
    <geometry>
      <mesh filename="package://ugv2_description/meshes/imu_sensor_1.stl" scale="0.001 0.001 0.001"/>
    </geometry>
    <material name="silver"/>
  </visual>
  <collision>
    <origin rpy="0 0 0" xyz="-0.0 -0.0 -0.01275"/>
    <geometry>
      <mesh filename="package://ugv2_description/meshes/imu_sensor_1.stl" scale="0.001 0.001 0.001"/>
    </geometry>
  </collision>
</link>

<joint name="lidar_joint" type="fixed">
  <origin rpy="0 0 0" xyz="0.0275 0.0 0.08275"/>
  <parent link="base_link"/>
  <child link="lidar_1"/>
</joint>

<joint name="rb_joint" type="continuous">
  <origin rpy="0 0 0" xyz="-0.075 -0.08 0.03775"/>
  <parent link="base_link"/>
  <child link="rb_wheel_1"/>
  <axis xyz="0.0 1.0 0.0"/>
</joint>

<joint name="rf_joint" type="continuous">
  <origin rpy="0 0 0" xyz="0.075 -0.08 0.03775"/>
  <parent link="base_link"/>
  <child link="rf_wheel_1"/>
  <axis xyz="0.0 1.0 0.0"/>
</joint>

<joint name="lb_joint" type="continuous">
  <origin rpy="0 0 0" xyz="-0.075 0.08 0.03775"/>
  <parent link="base_link"/>
  <child link="lb_wheel_1"/>
  <axis xyz="0.0 1.0 0.0"/>
</joint>

<joint name="lf_joint" type="continuous">
  <origin rpy="0 0 0" xyz="0.075 0.08 0.03775"/>
  <parent link="base_link"/>
  <child link="lf_wheel_1"/>
  <axis xyz="0.0 1.0 0.0"/>
</joint>

<joint name="pi_joint" type="fixed">
  <origin rpy="0 0 0" xyz="0.1 0.0 0.03775"/>
  <parent link="base_link"/>
  <child link="pi_camera_1"/>
</joint>

<joint name="imu_joint" type="fixed">
  <origin rpy="0 0 0" xyz="0.0 0.0 0.01275"/>
  <parent link="base_link"/>
  <child link="imu_sensor_1"/>
</joint>

</robot>
